Workbook

Sheet Instructions
A1: PVWood ERP v3 — BOMs
A3: ★ = required. Fill master data first (items / glue recipes must already exist).
A4: ONE ROW PER SKU. The row defines the product (sku_name, pieces_per_unit, dims) AND
A5: its recipe. Fill each component's code + qty; leave a cell blank if unused (e.g. no
A6: back veneer). Glue can differ face vs back (face_glue_code / back_glue_code).
A7: Coating (face/back _coating_code + g/M2) = a primer (door skins) OR a UV topcoat
A8: (panels). Fill only the side(s) that get coated — e.g. a door skin = base board +
A9: face_coating_code + packing; a UV-topcoat panel = its normal rows + a coating.
A10: Transform_PVS / Transform_PSP: recipe lines (kind = INPUT/OUTPUT/STEP), one row each.
A11: All *_code / *_sku cells reference codes you defined in the master-data workbook.

Sheet Assembly_BOM
A1: ★ product_sku | B1: sku_name | C1: pieces_per_unit | D1: thickness_mm | E1: width_mm | F1: length_mm | G1: base_board_code | H1: base_board_qty | I1: face_veneer_code | J1: face_veneer_qty | K1: face_glue_code | L1: face_glue_qty | M1: back_veneer_code | N1: back_veneer_qty | O1: back_glue_code | P1: back_glue_qty | Q1: face_coating_code | R1: Face_Coating_g/M2 | S1: back_coating_code | T1: Back_Coating_g/M2 | U1: packing_sku_code | V1: Notes
A2: 4ALMX5CC1 | B2: MDF/15.7*48.5*96.5 ALDER ALDER/ PC PC/ PM PM/ C C/ 0.5 0.5 | C2: 62 | D2: 15.7 | E2: 48.5 | F2: 96.5 | G2: BMCNX503 | H2: 62 | I2: XALPPC01 | J2: 62 | K2: Glue 09 | L2: 363.36997 | M2: XALPPC01 | N2: 62 | O2: Glue 09 | P2: 363.36997 | U2: PKG-CARTON | V2: 48
A3: 4ALMX5AC1 | B3: MDF/15.7*48.5*96.5 ALDER ALDER/ PC PC/ BM PM/ A C/ 0.5 0.5 | C3: 62 | D3: 15.7 | E3: 48.5 | F3: 96.5 | G3: BMCNX503 | H3: 62 | I3: XALPBA01 | J3: 62 | K3: Glue 09 | L3: 363.36997 | M3: XALPPC01 | N3: 62 | O3: Glue 09 | P3: 363.36997 | V3: 48
A4: 4ALBX9B21 | B4: PB/19*49*97 ALDER ALDER/ PC PC/ BM MPF/ B #2/ 0.5 0.5 | C4: 50 | D4: 19 | E4: 49 | F4: 97 | G4: BPCNX805 | H4: 50 | I4: XALPBB03 | J4: 50 | K4: Glue 09 | L4: 361.17656 | M4: XALPM201 | N4: 50 | O4: Glue 09 | P4: 361.17656 | V4: 48
A5: 4ALM52A11 | B5: MDF/5.2*48.5*96.5 ALDER ALDER/ PC PC/ BM MPF/ A #1/ 0.5 0.5 | C5: 160 | D5: 5.2 | E5: 48.5 | F5: 96.5 | G5: BMCN4206 | H5: 160 | I5: XALPBB03 | J5: 160 | K5: Glue 09 | L5: 363.36997 | M5: XALPM101 | N5: 150 | O5: Glue 09 | P5: 363.36997 | V5: 48
A6: 4ALM52A12 | B6: MDF/5.2*48.5*96.5 ALDER ALDER/ PC PC/ PM MPF/ A #1/ 0.5 0.5 | C6: 160 | D6: 5.2 | E6: 48.5 | F6: 96.5 | G6: BMCN4206 | H6: 160 | I6: XALPPA01 | J6: 160 | K6: Glue 09 | L6: 363.36997 | M6: XALPM101 | N6: 150 | O6: Glue 09 | P6: 363.36997 | V6: 48
A7: 4ALM52A21 | B7: MDF/5.2*48.5*96.5 ALDER ALDER/ PC PC/ PM MPF/ A #2/ 0.5 0.5 | C7: 160 | D7: 5.2 | E7: 48.5 | F7: 96.5 | G7: BMCN4206 | H7: 160 | I7: XALPPA01 | J7: 160 | K7: Glue 09 | L7: 363.36997 | M7: XALPM201 | N7: 160 | O7: Glue 09 | P7: 363.36997 | V7: 48
A8: 4ALM52AB1 | B8: MDF/5.2*48.5*96.5 ALDER ALDER/ PC PC/ BM BM/ A B/ 0.5 0.5 | C8: 150 | D8: 5.2 | E8: 48.5 | F8: 96.5 | G8: BMCN4206 | H8: 150 | I8: XALPBB03 | J8: 150 | K8: Glue 09 | L8: 363.36997 | M8: XALPBB01 | N8: 160 | O8: Glue 09 | P8: 363.36997 | V8: 48
A9: 4ALM52AB2 | B9: MDF/5.2*48.5*96.5 ALDER ALDER/ PC PC/ PM PM/ A B/ 0.5 0.5 | C9: 160 | D9: 5.2 | E9: 48.5 | F9: 96.5 | G9: BMCN4206 | H9: 160 | I9: XALPPA01 | J9: 160 | K9: Glue 09 | L9: 363.36997 | M9: XALPPB01 | N9: 160 | O9: Glue 09 | P9: 363.36997 | V9: 48
A10: 4ALM52AB3 | B10: MDF/5.2*48.5*96.5 ALDER ALDER/ PC PC/ BM PM/ A B/ 0.5 0.5 | C10: 160 | D10: 5.2 | E10: 48.5 | F10: 96.5 | G10: BMCN4206 | H10: 160 | I10: XALPBB03 | J10: 160 | K10: Glue 09 | L10: 363.36997 | M10: XALPPB01 | N10: 160 | O10: Glue 09 | P10: 363.36997 | V10: 48
A11: 4ALM52AB4 | B11: MDF/5.2*48.5*96.5 ALDER ALDER/ PC PC/ PM Horizontal PM Horizontal/ A B/ 0.5 0.5 | C11: 160 | D11: 5.2 | E11: 48.5 | F11: 96.5 | G11: BMCN4206 | H11: 160 | I11: XALPPA04 | J11: 160 | K11: Glue 09 | L11: 363.36997 | M11: XALPPB04 | N11: 160 | O11: Glue 09 | P11: 363.36997 | V11: 48
A12: 4ALM52B11 | B12: MDF/5.2*48.5*96.5 ALDER ALDER/ PC PC/ BM MPF/ B #1/ 0.5 0.5 | C12: 160 | D12: 5.2 | E12: 48.5 | F12: 96.5 | G12: BMCN4206 | H12: 160 | I12: XALPBB03 | J12: 160 | K12: Glue 09 | L12: 363.36997 | M12: XALPM101 | N12: 160 | O12: Glue 09 | P12: 363.36997 | V12: 48
A13: 4ALM52B12 | B13: MDF/5.2*48.5*96.5 ALDER ALDER/ PC PC/ PM MPF/ B #1/ 0.5 0.5 | C13: 160 | D13: 5.2 | E13: 48.5 | F13: 96.5 | G13: BMCN4206 | H13: 160 | I13: XALPPB03 | J13: 160 | K13: Glue 09 | L13: 363.36997 | M13: XALPM101 | N13: 160 | O13: Glue 09 | P13: 363.36997 | V13: 48
A14: 4ALM52B13 | B14: MDF/5.2*48.5*72.5 ALDER ALDER/ PC PC/ SM SM/ B #1/ 0.5 0.5 | C14: 160 | D14: 5.2 | E14: 48.5 | F14: 72.5 | G14: CB-BMCZ0405 | H14: 160 | I14: XALPSB01 | J14: 160 | K14: Glue 09 | L14: 277.1341 | M14: XALPM101 | N14: 160 | O14: Glue 09 | P14: 277.1341 | V14: 48
... A239: 4ROPX8B26 | B239: Platform TW/18*48.5*96.5 R.OAK R.OAK/ PC PC/ BM MPF/ B #2/ 0.5 0.5 | C239: 50 | D239: 18 | E239: 48.5 | F239: 96.5 | G239: BFCC1702 | H239: 50 | I239: XROPBB01 | J239: 50 | K239: Glue 09 | L239: 363.36997 | M239: XROPZF11 | N239: 180 | O239: Glue 02 | P239: 330.33634 | V239: 48
A240: 3CHP36KA1 | B240: MDF 2.7*36.5*84.5 CHERRY A PC BM Thick | C240: 240 | D240: 2.7 | E240: 36.5 | F240: 84.5 | G240: BMCN2508 | H240: 240 | I240: XCHPBA04 | J240: 240 | K240: Glue 09 | L240: 230.08355 | V240: 37
A241: 3CHP36KA2 | B241: MDF 2.7*36.5*96.5 CHERRY A PC BM Thick | C241: 240 | D241: 2.7 | E241: 36.5 | F241: 96.5 | G241: BMCN2510 | H241: 240 | I241: XCHPBA05 | J241: 240 | K241: Glue 09 | L241: 263.01392 | V241: 37
A242: 3CHP36KA3 | B242: MDF 2.7*36.5*108.5 CHERRY A PC BM Thick | C242: 240 | D242: 2.7 | E242: 36.5 | F242: 108.5 | G242: BMCN2513 | H242: 240 | I242: XCHPBA51 | J242: 240 | K242: Glue 09 | L242: 295.51524 | V242: 37
A243: 3CHP48KA1 | B243: MDF 2.7*48.5*96.5 CHERRY A PC BMPairMat.CenterBalanced Thick | C243: 240 | D243: 2.7 | E243: 48.5 | F243: 96.5 | G243: BMCN2511 | H243: 240 | I243: XCHPBA07 | J243: 240 | K243: Glue 09 | L243: 349.55033 | V243: 37
A244: 3CHP48KA2 | B244: MDF 2.7*48.5*96.5 CHERRY A PC BM Thick | C244: 240 | D244: 2.7 | E244: 48.5 | F244: 96.5 | G244: BMCN2511 | H244: 240 | I244: XCHPBA03 | J244: 240 | K244: Glue 09 | L244: 349.55033 | V244: 37
A245: 3ENR24NF1 | B245: MDF 2.7*24.5*80.5 EngineeredHardwood FD RC WPF Thin | C245: 240 | D245: 2.7 | E245: 24.5 | F245: 80.5 | G245: BMCN2501 | H245: 240 | I245: XENRWF81 | J245: 240 | K245: Glue 07 | L245: 126.23995 | V245: 37
A246: 3ENR28NF1 | B246: MDF 2.7*28.5*80.5 EngineeredHardwood FD RC WPF Thin | C246: 240 | D246: 2.7 | E246: 28.5 | F246: 80.5 | G246: BMCN2502 | H246: 240 | I246: XENRWF82 | J246: 240 | K246: Glue 07 | L246: 147.41568 | V246: 37
A247: 3ENR30NF1 | B247: MDF 2.7*30.5*80.5 EngineeredHardwood FD RC WPF Thin | C247: 240 | D247: 2.7 | E247: 30.5 | F247: 80.5 | G247: BMCN2503 | H247: 240 | I247: XENRWF83 | J247: 240 | K247: Glue 07 | L247: 157.79994 | V247: 37
A248: 3ENR32NF1 | B248: MDF 2.7*32.5*80.5 EngineeredHardwood FD RC WPF Thin | C248: 240 | D248: 2.7 | E248: 32.5 | F248: 80.5 | G248: BMCN2504 | H248: 240 | I248: XENRWF84 | J248: 240 | K248: Glue 07 | L248: 168.18419 | V248: 37
A249: 3ENR36NF1 | B249: MDF 2.7*36.5*80.5 EngineeredHardwood FD RC WPF Thin | C249: 240 | D249: 2.7 | E249: 36.5 | F249: 80.5 | G249: BMCN2509 | H249: 240 | I249: XENRWF85 | J249: 240 | K249: Glue 07 | L249: 188.74908 | V249: 37
A250: 3ENR36NF2 | B250: MDF 2.7*36.5*84.5 EngineeredHardwood FD RC WPF Thin | C250: 240 | D250: 2.7 | E250: 36.5 | F250: 84.5 | G250: BMCN2508 | H250: 240 | I250: XENRWF06 | J250: 240 | K250: Glue 07 | L250: 197.97887 | V250: 37
A251: 3ENR36NF3 | B251: MDF 2.7*36.5*96.5 EngineeredHardwood FD RC WPF Thin | C251: 240 | D251: 2.7 | E251: 36.5 | F251: 96.5 | G251: BMCN2510 | H251: 240 | I251: XENRWF86 | J251: 240 | K251: Glue 07 | L251: 226.31431 | V251: 37
... A371: 3WAP48KA2 | B371: MDF 2.7*48.5*108.5 WALNUT A PC BM Thick | C371: 240 | D371: 2.7 | E371: 48.5 | F371: 108.5 | G371: BMCN2512 | H371: 240 | I371: XWAPBA10 | J371: 240 | K371: Glue 09 | L371: 392.74517 | V371: 37
A372: MMBE5001 | B372: MDF 5*48*96 BEECH PC BM 0.15 | C372: 210 | D372: 5 | E372: 48 | F372: 96 | G372: BF2N4001 | H372: 210 | I372: XBEPZB01 | J372: 756 | K372: Glue 02 | L372: 240.31506 | V372: ME
A373: MMRO5001 | B373: MDF 5*48*96 R.OAK PC BM 0.2 | C373: 210 | D373: 5 | E373: 48 | F373: 96 | G373: BF2N4001 | H373: 210 | I373: XROPZF11 | J373: 756 | K373: Glue 02 | L373: 296.38858 | V373: ME
A374: MMRO5002 | B374: MDF 5*48*96 R.OAK PC SM 0.2 | C374: 210 | D374: 5 | E374: 48 | F374: 96 | G374: BF2N4001 | H374: 210 | I374: XROPZF11 | J374: 756 | K374: Glue 02 | L374: 296.38858 | V374: ME
A375: MMSA5001 | B375: MDF 5*48*96 SAPELE QC BM 0.13 | C375: 210 | D375: 5 | E375: 48 | F375: 96 | G375: BF2N4001 | H375: 210 | I375: XSAQZF01 | J375: 756 | K375: Glue 07 | L375: 240.31506 | V375: ME
A376: MMTE5001 | B376: MDF 5*48*96 TEAK QC Z 0.2 | C376: 210 | D376: 5 | E376: 48 | F376: 96 | G376: BF2N4001 | H376: 210 | I376: XTEQZF02 | J376: 756 | K376: Glue 05 | L376: 296.38858 | V376: ME
A377: MMWA5001 | B377: MDF 5*48*96 WALNUT PC BM 0.15 | C377: 210 | D377: 5 | E377: 48 | F377: 96 | G377: BF2N4001 | H377: 210 | I377: XWAPZF01 | J377: 756 | K377: Glue 05 | L377: 240.31506 | V377: ME
A378: UPM302603 | B378: MDF 3mm*730*2050 CARB P2 UV prime | C378: 220 | D378: =VLOOKUP(A378,'UV-CODE'!A:J,4,FALSE) -> 3 | E378: =VLOOKUP(A378,'UV-CODE'!A:J,7,FALSE) -> 730 | F378: =VLOOKUP(A378,'UV-CODE'!A:J,8,FALSE) -> 2050 | G378: BMCZ0281 | H378: =C378 -> 220 | Q378: 01-MAT-PUV-004 | R378: 25.39991 | S378: 010-MAT-PUV-002 | T378: 32.940897 | V378: UV
A379: UPM303604 | B379: MDF 3mm*780*2050 CARB P2 UV prime | C379: 220 | D379: =VLOOKUP(A379,'UV-CODE'!A:J,4,FALSE) -> 3 | E379: =VLOOKUP(A379,'UV-CODE'!A:J,7,FALSE) -> 780 | F379: =VLOOKUP(A379,'UV-CODE'!A:J,8,FALSE) -> 2050 | G379: BMCZ0282 | H379: =C379 -> 220 | Q379: 01-MAT-PUV-004 | R379: 24.687611 | S379: 010-MAT-PUV-002 | T379: 52.597211 | V379: UV
A380: UPM303607 | B380: MDF 3mm*830*2050 CARB P2 UV prime | C380: 220 | D380: =VLOOKUP(A380,'UV-CODE'!A:J,4,FALSE) -> 3 | E380: =VLOOKUP(A380,'UV-CODE'!A:J,7,FALSE) -> 830 | F380: =VLOOKUP(A380,'UV-CODE'!A:J,8,FALSE) -> 2050 | G380: BMCZ0283 | H380: =C380 -> 220 | Q380: 01-MAT-PUV-004 | R380: 19.525505 | S380: 010-MAT-PUV-002 | T380: 43.073252 | V380: UV
A381: SPM303703 | B381: MDF 3mm*36.5*80.5 CARB P2 Standard Primed | C381: 240 | D381: =VLOOKUP(A381,'UV-CODE'!A:J,4,FALSE) -> 3 | E381: =VLOOKUP(A381,'UV-CODE'!A:K,5,FALSE) -> 36.5 | F381: =VLOOKUP(A381,'UV-CODE'!A:K,6,FALSE) -> 80.5 | G381: BMCZ029J | H381: =C381 -> 240 | Q381: 01-MAT-PUV-004 | R381: 41.21 | S381: 010-MAT-PUV-002 | T381: - | V381: UV
A382: SPM303702 | B382: MDF 3mm*32.5*80.5 CARB P2 Standard Primed | C382: 240 | D382: =VLOOKUP(A382,'UV-CODE'!A:J,4,FALSE) -> 3 | E382: =VLOOKUP(A382,'UV-CODE'!A:K,5,FALSE) -> 32.5 | F382: =VLOOKUP(A382,'UV-CODE'!A:K,6,FALSE) -> 80.5 | G382: BMCZ029D | H382: =C382 -> 240 | Q382: 01-MAT-PUV-004 | R382: 41.31 | S382: 010-MAT-PUV-002 | T382: - | V382: UV
A383: SPM303701 | B383: MDF 3mm*30.5*80.5 CARB P2 Standard Primed | C383: 240 | D383: =VLOOKUP(A383,'UV-CODE'!A:J,4,FALSE) -> 3 | E383: =VLOOKUP(A383,'UV-CODE'!A:K,5,FALSE) -> 30.5 | F383: =VLOOKUP(A383,'UV-CODE'!A:K,6,FALSE) -> 80.5 | G383: BMCZ029B | H383: =C383 -> 240 | Q383: 01-MAT-PUV-004 | R383: 40.15 | S383: 010-MAT-PUV-002 | T383: - | V383: UV
...

Sheet Transform_PVS
A1: ★ recipe_code | B1: ★ name | C1: ★ kind | D1: seq | E1: item_code | F1: role | G1: qty | H1: uom | I1: grade | J1: Thickness_mm | K1: Length_mm | L1: FSC | M1: expected_yield_pct | N1: expected_loss_pct | O1: notes
A2: PVS-LRO4S | B2: Red Oak Log Slicing A | C2: INPUT | D2: 1 | E2: LRO4S | F2: log | H2: m3 | I2: A | J2: - | K2: - | L2: - | M2: 46 | N2: 54 | O2: Actual input and output quantities will be recorded after production.
A3: PVS-LRO4S | B3: Red Oak Log Slicing A | C3: OUTPUT | D3: 2 | E3: XROPZ101 | F3: veneer | H3: m2 | I3: 1# | J3: 0.3 | K3: 2700 | L3: -
A4: PVS-LRO4S | B4: Red Oak Log Slicing A | C4: OUTPUT | D4: 2 | E4: XROPZ102 | F4: veneer | H4: m2 | I4: 1# | J4: 0.2 | K4: 2700 | L4: -
A5: PVS-LRO4S | B5: Red Oak Log Slicing A | C5: OUTPUT | D5: 2 | E5: XROPZ103 | F5: veneer | H5: m2 | I5: 1# | J5: 0.35 | K5: 2700 | L5: -
A6: PVS-LRO4S | B6: Red Oak Log Slicing A | C6: OUTPUT | D6: 2 | E6: XROPZ203 | F6: veneer | H6: m2 | I6: 2# | J6: 0.2 | K6: 2700 | L6: -
A7: PVS-LRO4S | B7: Red Oak Log Slicing A | C7: OUTPUT | D7: 2 | E7: XROPZ204 | F7: veneer | H7: m2 | I7: 2# | J7: 0.2 | K7: 2700 | L7: -
A8: PVS-LRO4S | B8: Red Oak Log Slicing A | C8: OUTPUT | D8: 2 | E8: XROPZ405 | F8: veneer | H8: m2 | I8: 4# | J8: 0.2 | K8: 2700 | L8: -
A9: PVS-LRO4S | B9: Red Oak Log Slicing A | C9: OUTPUT | D9: 2 | E9: XROPZF02 | F9: veneer | H9: m2 | I9: FD | J9: 0.2 | K9: 2200 | L9: -
A10: PVS-LRO3S | B10: Red Oak Log Slicing B | C10: INPUT | D10: 1 | E10: LRO3S | F10: log | H10: m3 | I10: B | J10: - | K10: - | L10: - | M10: 46 | N10: 54
A11: PVS-LRO3S | B11: Red Oak Log Slicing B | C11: OUTPUT | D11: 2 | E11: XROPZ101 | F11: veneer | H11: m2 | I11: 1# | J11: 0.3 | K11: 2700 | L11: -
A12: PVS-LRO3S | B12: Red Oak Log Slicing B | C12: OUTPUT | D12: 2 | E12: XROPZ102 | F12: veneer | H12: m2 | I12: 1# | J12: 0.2 | K12: 2700 | L12: -
A13: PVS-LRO3S | B13: Red Oak Log Slicing B | C13: OUTPUT | D13: 2 | E13: XROPZ103 | F13: veneer | H13: m2 | I13: 1# | J13: 0.35 | K13: 2700 | L13: -
A14: PVS-LRO3S | B14: Red Oak Log Slicing B | C14: OUTPUT | D14: 2 | E14: XROPZ203 | F14: veneer | H14: m2 | I14: 2# | J14: 0.2 | K14: 2700 | L14: -
A15: PVS-LRO3S | B15: Red Oak Log Slicing B | C15: OUTPUT | D15: 2 | E15: XROPZ204 | F15: veneer | H15: m2 | I15: 2# | J15: 0.2 | K15: 2700 | L15: -
A16: PVS-LRO3S | B16: Red Oak Log Slicing B | C16: OUTPUT | D16: 2 | E16: XROPZ405 | F16: veneer | H16: m2 | I16: 4# | J16: 0.2 | K16: 2700 | L16: -
A17: PVS-LRO3S | B17: Red Oak Log Slicing B | C17: OUTPUT | D17: 2 | E17: XROPZF02 | F17: veneer | H17: m2 | I17: FD | J17: 0.2 | K17: 2200 | L17: -
A18: PVS-LRO4F | B18: Red Oak Log Slicing A FSC | C18: INPUT | D18: 1 | E18: LRO4F | F18: log | H18: m3 | I18: A | J18: - | K18: - | L18: FSC CW | M18: 46 | N18: 54
A19: PVS-LRO4F | B19: Red Oak Log Slicing A FSC | C19: OUTPUT | D19: 2 | E19: XROPZ204 | F19: veneer | H19: m2 | I19: 2# | J19: 0.2 | K19: 2700 | L19: FSC CW
A20: PVS-LRO4F | B20: Red Oak Log Slicing A FSC | C20: OUTPUT | D20: 2 | E20: XROPZ405 | F20: veneer | H20: m2 | I20: 4# | J20: 0.2 | K20: 2700 | L20: FSC CW
A21: PVS-LRO4F | B21: Red Oak Log Slicing A FSC | C21: OUTPUT | D21: 2 | E21: XROPZF04 | F21: veneer | H21: m2 | I21: FD | J21: 0.2 | K21: 2700 | L21: FSC CW
A22: PVS-LRO4F | B22: Red Oak Log Slicing A FSC | C22: OUTPUT | D22: 2 | E22: XROPZF05 | F22: veneer | H22: m2 | I22: FD | J22: 0.2 | K22: 2200 | L22: FSC CW

Sheet Transform_PSP
A1: ★ recipe_code | B1: ★ name | C1: ★ kind | D1: seq | E1: item_code | F1: role | G1: qty | H1: uom | I1: grade | J1: cut | K1: mat | L1: Thickness_mm | M1: width_mm | N1: length_mm | O1: expected_yield_pct | P1: expected_loss_pct | Q1: notes
A2: PSP-YWOFA801 | B2: YWOFA801 Splicing | C2: INPUT | D2: 1 | E2: YWOFA801 | F2: veneer | H2: m2 | I2: PAA | J2: =VLOOKUP(E2,'M2'!A:K,7,FALSE) -> RIFT | K2: =VLOOKUP(E2,'M2'!A:K,9,FALSE) -> Z | L2: =VLOOKUP(E2,'M2'!A:K,3,FALSE) -> 0.5 | M2: =VLOOKUP(E2,'M2'!A:K,4,FALSE) -> NON | N2: =VLOOKUP(E2,'M2'!A:K,5,FALSE) -> 2500 | O2: 60 | P2: 40 | Q2: Actual input and output quantities will be recorded after production.
A3: PSP-YWOFA801 | B3: YWOFA801 Splicing | C3: OUTPUT | D3: 2 | E3: XWOFZW01 | F3: veneer | H3: pcs. | I3: WF | J3: =VLOOKUP(E3,V!A:K,7,FALSE) -> RIFT | K3: =VLOOKUP(E3,V!A:K,9,FALSE) -> Z | L3: =VLOOKUP(E3,V!A:K,3,FALSE) -> 0.5 | M3: =VLOOKUP(E3,V!A:K,4,FALSE) -> 1265 | N3: =VLOOKUP(E3,V!A:K,5,FALSE) -> 2520
A4: PSP-YWOFA801 | B4: YWOFA801 Splicing | C4: OUTPUT | D4: 2 | E4: XWOFZW02 | F4: veneer | H4: pcs. | I4: WF | J4: =VLOOKUP(E4,V!A:K,7,FALSE) -> RIFT | K4: =VLOOKUP(E4,V!A:K,9,FALSE) -> Z | L4: =VLOOKUP(E4,V!A:K,3,FALSE) -> 0.5 | M4: =VLOOKUP(E4,V!A:K,4,FALSE) -> 1265 | N4: =VLOOKUP(E4,V!A:K,5,FALSE) -> 3100
A5: PSP-YWOFA801 | B5: YWOFA801 Splicing | C5: OUTPUT | D5: 2 | E5: XWOFZW06 | F5: veneer | H5: pcs. | I5: WF | J5: =VLOOKUP(E5,V!A:K,7,FALSE) -> RIFT | K5: =VLOOKUP(E5,V!A:K,9,FALSE) -> Z | L5: =VLOOKUP(E5,V!A:K,3,FALSE) -> 0.5 | M5: =VLOOKUP(E5,V!A:K,4,FALSE) -> 965 | N5: =VLOOKUP(E5,V!A:K,5,FALSE) -> 2250
A6: PSP-YWOFB801 | B6: YWOFB801 Splicing | C6: INPUT | D6: 1 | E6: YWOFB801 | F6: veneer | H6: m2 | I6: PB | J6: =VLOOKUP(E6,'M2'!A:K,7,FALSE) -> RIFT | K6: =VLOOKUP(E6,'M2'!A:K,9,FALSE) -> Z | L6: =VLOOKUP(E6,'M2'!A:K,3,FALSE) -> 0.5 | M6: =VLOOKUP(E6,'M2'!A:K,4,FALSE) -> NON | N6: =VLOOKUP(E6,'M2'!A:K,5,FALSE) -> 2500 | O6: 60 | P6: 40
A7: PSP-YWOFB801 | B7: YWOFB801 Splicing | C7: OUTPUT | D7: 2 | E7: XWOPZW02 | F7: veneer | H7: pcs. | I7: WF | J7: =VLOOKUP(E7,V!A:K,7,FALSE) -> PC | K7: =VLOOKUP(E7,V!A:K,9,FALSE) -> Z | L7: =VLOOKUP(E7,V!A:K,3,FALSE) -> 0.5 | M7: =VLOOKUP(E7,V!A:K,4,FALSE) -> 1265 | N7: =VLOOKUP(E7,V!A:K,5,FALSE) -> 3100
A8: PSP-YWOFB801 | B8: YWOFB801 Splicing | C8: OUTPUT | D8: 3 | E8: XWOFZW02 | F8: veneer | H8: pcs. | I8: WF | J8: =VLOOKUP(E8,V!A:K,7,FALSE) -> RIFT | K8: =VLOOKUP(E8,V!A:K,9,FALSE) -> Z | L8: =VLOOKUP(E8,V!A:K,3,FALSE) -> 0.5 | M8: =VLOOKUP(E8,V!A:K,4,FALSE) -> 1265 | N8: =VLOOKUP(E8,V!A:K,5,FALSE) -> 3100
A9: PSP-YWOFB801 | B9: YWOFB801 Splicing | C9: OUTPUT | D9: 4 | E9: XWOFZW01 | F9: veneer | H9: pcs. | I9: WF | J9: =VLOOKUP(E9,V!A:K,7,FALSE) -> RIFT | K9: =VLOOKUP(E9,V!A:K,9,FALSE) -> Z | L9: =VLOOKUP(E9,V!A:K,3,FALSE) -> 0.5 | M9: =VLOOKUP(E9,V!A:K,4,FALSE) -> 1265 | N9: =VLOOKUP(E9,V!A:K,5,FALSE) -> 2520
A10: PSP-YWOFB802 | B10: YWOFB802 Splicing | C10: INPUT | D10: 1 | E10: YWOFB802 | F10: veneer | H10: m2 | I10: PB | J10: =VLOOKUP(E10,'M2'!A:K,7,FALSE) -> RIFT | K10: =VLOOKUP(E10,'M2'!A:K,9,FALSE) -> Z | L10: =VLOOKUP(E10,'M2'!A:K,3,FALSE) -> 0.4 | M10: =VLOOKUP(E10,'M2'!A:K,4,FALSE) -> NON | N10: =VLOOKUP(E10,'M2'!A:K,5,FALSE) -> 2500 | O10: 60 | P10: 40
A11: PSP-YWOFB802 | B11: YWOFB802 Splicing | C11: OUTPUT | D11: 2 | E11: XWOFZW05 | F11: veneer | H11: pcs. | I11: WF | J11: =VLOOKUP(E11,V!A:K,7,FALSE) -> RIFT | K11: =VLOOKUP(E11,V!A:K,9,FALSE) -> Z | L11: =VLOOKUP(E11,V!A:K,3,FALSE) -> 0.4 | M11: =VLOOKUP(E11,V!A:K,4,FALSE) -> 965 | N11: =VLOOKUP(E11,V!A:K,5,FALSE) -> 2250
A12: PSP-YWOFB802 | B12: YWOFB802 Splicing | C12: OUTPUT | D12: 3 | E12: XWOFZW03 | F12: veneer | H12: pcs. | I12: WF | J12: =VLOOKUP(E12,V!A:K,7,FALSE) -> RIFT | K12: =VLOOKUP(E12,V!A:K,9,FALSE) -> Z | L12: =VLOOKUP(E12,V!A:K,3,FALSE) -> 0.4 | M12: =VLOOKUP(E12,V!A:K,4,FALSE) -> 1265 | N12: =VLOOKUP(E12,V!A:K,5,FALSE) -> 2520
A13: PSP-YWOFB802 | B13: YWOFB802 Splicing | C13: OUTPUT | D13: 4 | E13: XWOFZW04 | F13: veneer | H13: pcs. | I13: WF | J13: =VLOOKUP(E13,V!A:K,7,FALSE) -> RIFT | K13: =VLOOKUP(E13,V!A:K,9,FALSE) -> Z | L13: =VLOOKUP(E13,V!A:K,3,FALSE) -> 0.4 | M13: =VLOOKUP(E13,V!A:K,4,FALSE) -> 1265 | N13: =VLOOKUP(E13,V!A:K,5,FALSE) -> 3100
A14: PSP-YWOFB802 | B14: YWOFB802 Splicing | C14: OUTPUT | D14: 5 | E14: XWOPZW04 | F14: veneer | H14: pcs. | I14: WF | J14: =VLOOKUP(E14,V!A:K,7,FALSE) -> PC | K14: =VLOOKUP(E14,V!A:K,9,FALSE) -> Z | L14: =VLOOKUP(E14,V!A:K,3,FALSE) -> 0.4 | M14: =VLOOKUP(E14,V!A:K,4,FALSE) -> 1265 | N14: =VLOOKUP(E14,V!A:K,5,FALSE) -> 2520
A15: PSP-YWOFB802 | B15: YWOFB802 Splicing | C15: OUTPUT | D15: 6 | E15: XWOFZW08 | F15: veneer | H15: pcs. | I15: WF | J15: =VLOOKUP(E15,V!A:K,7,FALSE) -> RIFT | K15: =VLOOKUP(E15,V!A:K,9,FALSE) -> Z | L15: =VLOOKUP(E15,V!A:K,3,FALSE) -> 0.4 | M15: =VLOOKUP(E15,V!A:K,4,FALSE) -> 965 | N15: =VLOOKUP(E15,V!A:K,5,FALSE) -> 2520
A16: PSP-YWOFB802 | B16: YWOFB802 Splicing | C16: OUTPUT | D16: 7 | E16: XWOPZW09 | F16: veneer | H16: pcs. | I16: WF | J16: =VLOOKUP(E16,V!A:K,7,FALSE) -> PC | K16: =VLOOKUP(E16,V!A:K,9,FALSE) -> Z | L16: =VLOOKUP(E16,V!A:K,3,FALSE) -> 0.4 | M16: =VLOOKUP(E16,V!A:K,4,FALSE) -> 965 | N16: =VLOOKUP(E16,V!A:K,5,FALSE) -> 2520
A17: PSP-YWOFB802 | B17: YWOFB802 Splicing | C17: OUTPUT | D17: 8 | E17: XWOFZW01 | F17: veneer | H17: pcs. | I17: WF | J17: =VLOOKUP(E17,V!A:K,7,FALSE) -> RIFT | K17: =VLOOKUP(E17,V!A:K,9,FALSE) -> Z | L17: =VLOOKUP(E17,V!A:K,3,FALSE) -> 0.5 | M17: =VLOOKUP(E17,V!A:K,4,FALSE) -> 1265 | N17: =VLOOKUP(E17,V!A:K,5,FALSE) -> 2520
A18: PSP-YWOFA802 | B18: YWOFA802 Splicing | C18: INPUT | D18: 1 | E18: YWOFA802 | F18: veneer | H18: m2 | I18: PAA | J18: =VLOOKUP(E18,'M2'!A:K,7,FALSE) -> RIFT | K18: =VLOOKUP(E18,'M2'!A:K,9,FALSE) -> Z | L18: =VLOOKUP(E18,'M2'!A:K,3,FALSE) -> 0.4 | M18: =VLOOKUP(E18,'M2'!A:K,4,FALSE) -> NON | N18: =VLOOKUP(E18,'M2'!A:K,5,FALSE) -> 2500 | O18: 60 | P18: 40
A19: PSP-YWOFA802 | B19: YWOFA802 Splicing | C19: OUTPUT | D19: 2 | E19: XWOFZW04 | F19: veneer | H19: pcs. | I19: WF | J19: =VLOOKUP(E19,V!A:K,7,FALSE) -> RIFT | K19: =VLOOKUP(E19,V!A:K,9,FALSE) -> Z | L19: =VLOOKUP(E19,V!A:K,3,FALSE) -> 0.4 | M19: =VLOOKUP(E19,V!A:K,4,FALSE) -> 1265 | N19: =VLOOKUP(E19,V!A:K,5,FALSE) -> 3100
A20: PSP-YWOFA802 | B20: YWOFA802 Splicing | C20: OUTPUT | D20: 3 | E20: XWOFZW03 | F20: veneer | H20: pcs. | I20: WF | J20: =VLOOKUP(E20,V!A:K,7,FALSE) -> RIFT | K20: =VLOOKUP(E20,V!A:K,9,FALSE) -> Z | L20: =VLOOKUP(E20,V!A:K,3,FALSE) -> 0.4 | M20: =VLOOKUP(E20,V!A:K,4,FALSE) -> 1265 | N20: =VLOOKUP(E20,V!A:K,5,FALSE) -> 2520
A21: PSP-YWOFA802 | B21: YWOFA802 Splicing | C21: OUTPUT | D21: 2 | E21: XWOPZW04 | F21: veneer | H21: pcs. | I21: WF | J21: =VLOOKUP(E21,V!A:K,7,FALSE) -> PC | K21: =VLOOKUP(E21,V!A:K,9,FALSE) -> Z | L21: =VLOOKUP(E21,V!A:K,3,FALSE) -> 0.4 | M21: =VLOOKUP(E21,V!A:K,4,FALSE) -> 1265 | N21: =VLOOKUP(E21,V!A:K,5,FALSE) -> 2520
A22: PSP-YWOFA802 | B22: YWOFA802 Splicing | C22: OUTPUT | D22: 4 | E22: XWOFZW05 | F22: veneer | H22: pcs. | I22: WF | J22: =VLOOKUP(E22,V!A:K,7,FALSE) -> RIFT | K22: =VLOOKUP(E22,V!A:K,9,FALSE) -> Z | L22: =VLOOKUP(E22,V!A:K,3,FALSE) -> 0.4 | M22: =VLOOKUP(E22,V!A:K,4,FALSE) -> 965 | N22: =VLOOKUP(E22,V!A:K,5,FALSE) -> 2250
A23: PSP-YWOFA802 | B23: YWOFA802 Splicing | C23: OUTPUT | D23: 5 | E23: XWOFZW08 | F23: veneer | H23: pcs. | I23: WF | J23: =VLOOKUP(E23,V!A:K,7,FALSE) -> RIFT | K23: =VLOOKUP(E23,V!A:K,9,FALSE) -> Z | L23: =VLOOKUP(E23,V!A:K,3,FALSE) -> 0.4 | M23: =VLOOKUP(E23,V!A:K,4,FALSE) -> 965 | N23: =VLOOKUP(E23,V!A:K,5,FALSE) -> 2520
A24: PSP-YWOFA802 | B24: YWOFA802 Splicing | C24: OUTPUT | D24: 3 | E24: XWOFZW01 | F24: veneer | H24: pcs. | I24: WF | J24: =VLOOKUP(E24,V!A:K,7,FALSE) -> RIFT | K24: =VLOOKUP(E24,V!A:K,9,FALSE) -> Z | L24: =VLOOKUP(E24,V!A:K,3,FALSE) -> 0.5 | M24: =VLOOKUP(E24,V!A:K,4,FALSE) -> 1265 | N24: =VLOOKUP(E24,V!A:K,5,FALSE) -> 2520
A25: PSP-YWOFA802 | B25: YWOFA802 Splicing | C25: OUTPUT | D25: 6 | E25: XWOFZW09 | F25: veneer | H25: pcs. | I25: WF | J25: =VLOOKUP(E25,V!A:K,7,FALSE) -> RIFT | K25: =VLOOKUP(E25,V!A:K,9,FALSE) -> Z | L25: =VLOOKUP(E25,V!A:K,3,FALSE) -> 0.4 | M25: =VLOOKUP(E25,V!A:K,4,FALSE) -> 965 | N25: =VLOOKUP(E25,V!A:K,5,FALSE) -> 2800
A26: PSP-YWOPA801 | B26: YWOPA801 Splicing | C26: INPUT | D26: 1 | E26: YWOPA801 | F26: veneer | H26: m2 | I26: PA | J26: =VLOOKUP(E26,'M2'!A:K,7,FALSE) -> PC | K26: =VLOOKUP(E26,'M2'!A:K,9,FALSE) -> Z | L26: =VLOOKUP(E26,'M2'!A:K,3,FALSE) -> 0.4 | M26: =VLOOKUP(E26,'M2'!A:K,4,FALSE) -> NON | N26: =VLOOKUP(E26,'M2'!A:K,5,FALSE) -> 2500 | O26: 60 | P26: 40
A27: PSP-YWOPA801 | B27: YWOPA801 Splicing | C27: OUTPUT | D27: 2 | E27: XWOPZW03 | F27: veneer | H27: pcs. | I27: WF | J27: =VLOOKUP(E27,V!A:K,7,FALSE) -> PC | K27: =VLOOKUP(E27,V!A:K,9,FALSE) -> Z | L27: =VLOOKUP(E27,V!A:K,3,FALSE) -> 0.4 | M27: =VLOOKUP(E27,V!A:K,4,FALSE) -> 1265 | N27: =VLOOKUP(E27,V!A:K,5,FALSE) -> 3100
A28: PSP-YWOPA801 | B28: YWOPA801 Splicing | C28: OUTPUT | D28: 2 | E28: XWOFZW04 | F28: veneer | H28: pcs. | I28: WF | J28: =VLOOKUP(E28,V!A:K,7,FALSE) -> RIFT | K28: =VLOOKUP(E28,V!A:K,9,FALSE) -> Z | L28: =VLOOKUP(E28,V!A:K,3,FALSE) -> 0.4 | M28: =VLOOKUP(E28,V!A:K,4,FALSE) -> 1265 | N28: =VLOOKUP(E28,V!A:K,5,FALSE) -> 3100
A29: PSP-YWOPA801 | B29: YWOPA801 Splicing | C29: OUTPUT | D29: 3 | E29: XWOFZW03 | F29: veneer | H29: pcs. | I29: WF | J29: =VLOOKUP(E29,V!A:K,7,FALSE) -> RIFT | K29: =VLOOKUP(E29,V!A:K,9,FALSE) -> Z | L29: =VLOOKUP(E29,V!A:K,3,FALSE) -> 0.4 | M29: =VLOOKUP(E29,V!A:K,4,FALSE) -> 1265 | N29: =VLOOKUP(E29,V!A:K,5,FALSE) -> 2520
A30: PSP-YWOPA801 | B30: YWOPA801 Splicing | C30: OUTPUT | D30: 3 | E30: XWOPZW09 | F30: veneer | H30: pcs. | I30: WF | J30: =VLOOKUP(E30,V!A:K,7,FALSE) -> PC | K30: =VLOOKUP(E30,V!A:K,9,FALSE) -> Z | L30: =VLOOKUP(E30,V!A:K,3,FALSE) -> 0.4 | M30: =VLOOKUP(E30,V!A:K,4,FALSE) -> 965 | N30: =VLOOKUP(E30,V!A:K,5,FALSE) -> 2520
A31: PSP-YWOPA801 | B31: YWOPA801 Splicing | C31: OUTPUT | D31: 4 | E31: XWOPZW04 | F31: veneer | H31: pcs. | I31: WF | J31: =VLOOKUP(E31,V!A:K,7,FALSE) -> PC | K31: =VLOOKUP(E31,V!A:K,9,FALSE) -> Z | L31: =VLOOKUP(E31,V!A:K,3,FALSE) -> 0.4 | M31: =VLOOKUP(E31,V!A:K,4,FALSE) -> 1265 | N31: =VLOOKUP(E31,V!A:K,5,FALSE) -> 2520
A32: PSP-YWOPA801 | B32: YWOPA801 Splicing | C32: OUTPUT | D32: 4 | E32: XWOPZW01 | F32: veneer | H32: pcs. | I32: WF | J32: =VLOOKUP(E32,V!A:K,7,FALSE) -> PC | K32: =VLOOKUP(E32,V!A:K,9,FALSE) -> Z | L32: =VLOOKUP(E32,V!A:K,3,FALSE) -> 0.5 | M32: =VLOOKUP(E32,V!A:K,4,FALSE) -> 1265 | N32: =VLOOKUP(E32,V!A:K,5,FALSE) -> 2520
A33: PSP-XWOFZA09 | B33: XWOFZA09 Splicing | C33: INPUT | D33: 1 | E33: XWOFZA09 | F33: veneer | H33: m2 | I33: AB | J33: =VLOOKUP(E33,'M2'!A:K,7,FALSE) -> RIFT | K33: =VLOOKUP(E33,'M2'!A:K,9,FALSE) -> Z | L33: =VLOOKUP(E33,'M2'!A:K,3,FALSE) -> 0.4 | M33: =VLOOKUP(E33,'M2'!A:K,4,FALSE) -> NON | N33: =VLOOKUP(E33,'M2'!A:K,5,FALSE) -> 2500+ | O33: 60 | P33: 40
A34: PSP-XWOFZA09 | B34: XWOFZA09 Splicing | C34: OUTPUT | D34: 2 | E34: XWOFZW03 | F34: veneer | H34: pcs. | I34: WF | J34: =VLOOKUP(E34,V!A:K,7,FALSE) -> RIFT | K34: =VLOOKUP(E34,V!A:K,9,FALSE) -> Z | L34: =VLOOKUP(E34,V!A:K,3,FALSE) -> 0.4 | M34: =VLOOKUP(E34,V!A:K,4,FALSE) -> 1265 | N34: =VLOOKUP(E34,V!A:K,5,FALSE) -> 2520
A35: PSP-XWOFZA09 | B35: XWOFZA09 Splicing | C35: OUTPUT | D35: 3 | E35: XWOFZW04 | F35: veneer | H35: pcs. | I35: WF | J35: =VLOOKUP(E35,V!A:K,7,FALSE) -> RIFT | K35: =VLOOKUP(E35,V!A:K,9,FALSE) -> Z | L35: =VLOOKUP(E35,V!A:K,3,FALSE) -> 0.4 | M35: =VLOOKUP(E35,V!A:K,4,FALSE) -> 1265 | N35: =VLOOKUP(E35,V!A:K,5,FALSE) -> 3100
A36: PSP-XWOFZA09 | B36: XWOFZA09 Splicing | C36: OUTPUT | D36: 4 | E36: XWOFZW05 | F36: veneer | H36: pcs. | I36: WF | J36: =VLOOKUP(E36,V!A:K,7,FALSE) -> RIFT | K36: =VLOOKUP(E36,V!A:K,9,FALSE) -> Z | L36: =VLOOKUP(E36,V!A:K,3,FALSE) -> 0.4 | M36: =VLOOKUP(E36,V!A:K,4,FALSE) -> 965 | N36: =VLOOKUP(E36,V!A:K,5,FALSE) -> 2250
A37: PSP-XWOFZA09 | B37: XWOFZA09 Splicing | C37: OUTPUT | D37: 5 | E37: XWOFZW08 | F37: veneer | H37: pcs. | I37: WF | J37: =VLOOKUP(E37,V!A:K,7,FALSE) -> RIFT | K37: =VLOOKUP(E37,V!A:K,9,FALSE) -> Z | L37: =VLOOKUP(E37,V!A:K,3,FALSE) -> 0.4 | M37: =VLOOKUP(E37,V!A:K,4,FALSE) -> 965 | N37: =VLOOKUP(E37,V!A:K,5,FALSE) -> 2520
A38: PSP-XWOFZA09 | B38: XWOFZA09 Splicing | C38: OUTPUT | D38: 6 | E38: XWOFZW09 | F38: veneer | H38: pcs. | I38: WF | J38: =VLOOKUP(E38,V!A:K,7,FALSE) -> RIFT | K38: =VLOOKUP(E38,V!A:K,9,FALSE) -> Z | L38: =VLOOKUP(E38,V!A:K,3,FALSE) -> 0.4 | M38: =VLOOKUP(E38,V!A:K,4,FALSE) -> 965 | N38: =VLOOKUP(E38,V!A:K,5,FALSE) -> 2800
A39: PSP-XWOPZA06 | B39: XWOPZA06 Splicing | C39: INPUT | D39: 1 | E39: XWOPZA06 | F39: veneer | H39: m2 | I39: A | J39: =VLOOKUP(E39,'M2'!A:K,7,FALSE) -> PC | K39: =VLOOKUP(E39,'M2'!A:K,9,FALSE) -> Z | L39: =VLOOKUP(E39,'M2'!A:K,3,FALSE) -> 0.4 | M39: =VLOOKUP(E39,'M2'!A:K,4,FALSE) -> NON | N39: =VLOOKUP(E39,'M2'!A:K,5,FALSE) -> 2500+ | O39: 60 | P39: 40
A40: PSP-XWOPZA06 | B40: XWOPZA06 Splicing | C40: OUTPUT | D40: 2 | E40: XWOPZW08 | F40: veneer | H40: pcs. | I40: WF | J40: =VLOOKUP(E40,V!A:K,7,FALSE) -> PC | K40: =VLOOKUP(E40,V!A:K,9,FALSE) -> Z | L40: =VLOOKUP(E40,V!A:K,3,FALSE) -> 0.4 | M40: =VLOOKUP(E40,V!A:K,4,FALSE) -> 965 | N40: =VLOOKUP(E40,V!A:K,5,FALSE) -> 2250
...

Sheet UV-CODE
A1: FG-CODE | B1: species | C1: Baseboard | D1: Thickness(mm) | E1: Width-Inch | F1: Length-Inch | G1: Width-mm | H1: Length-mm | I1: Unit | J1: GLUE | K1: NAME
A2: SPM292701 | B2: Standard Primed | C2: MDF | D2: 2.9 | E2: 24.5 | F2: 80.5 | G2: 620 | H2: 2045 | I2: Pcs | J2: CARB P2 | K2: =C2&" "&D2&"mm"&""&"*"&E2&"*"&F2&" "&J2&" "&B2 -> MDF 2.9mm*24.5*80.5 CARB P2 Standard Primed
A3: SPM292702 | B3: Standard Primed | C3: MDF | D3: 2.9 | E3: 28.5 | F3: 80.5 | G3: 724 | H3: 2045 | I3: Pcs | J3: CARB P2 | K3: =C3&" "&D3&"mm"&""&"*"&E3&"*"&F3&" "&J3&" "&B3 -> MDF 2.9mm*28.5*80.5 CARB P2 Standard Primed
A4: SPM293704 | B4: Standard Primed | C4: MDF | D4: 2.9 | E4: 30.5 | F4: 80.5 | G4: 775 | H4: 2045 | I4: Pcs | J4: CARB P2 | K4: =C4&" "&D4&"mm"&""&"*"&E4&"*"&F4&" "&J4&" "&B4 -> MDF 2.9mm*30.5*80.5 CARB P2 Standard Primed
A5: SPM293705 | B5: Standard Primed | C5: MDF | D5: 2.9 | E5: 32.5 | F5: 80.5 | G5: 826 | H5: 2045 | I5: Pcs | J5: CARB P2 | K5: =C5&" "&D5&"mm"&""&"*"&E5&"*"&F5&" "&J5&" "&B5 -> MDF 2.9mm*32.5*80.5 CARB P2 Standard Primed
A6: SPM293701 | B6: Standard Primed | C6: MDF | D6: 2.9 | E6: 36.5 | F6: 80.5 | G6: 927 | H6: 2045 | I6: Pcs | J6: CARB P2 | K6: =C6&" "&D6&"mm"&""&"*"&E6&"*"&F6&" "&J6&" "&B6 -> MDF 2.9mm*36.5*80.5 CARB P2 Standard Primed
A7: SPM293702 | B7: Standard Primed | C7: MDF | D7: 2.9 | E7: 36.5 | F7: 84.5 | G7: 927 | H7: 2145 | I7: Pcs | J7: CARB P2 | K7: =C7&" "&D7&"mm"&""&"*"&E7&"*"&F7&" "&J7&" "&B7 -> MDF 2.9mm*36.5*84.5 CARB P2 Standard Primed
A8: SPM293801 | B8: Standard Primed | C8: MDF | D8: 2.9 | E8: 36.5 | F8: 96.5 | G8: 927 | H8: 2452 | I8: Pcs | J8: CARB P2 | K8: =C8&" "&D8&"mm"&""&"*"&E8&"*"&F8&" "&J8&" "&B8 -> MDF 2.9mm*36.5*96.5 CARB P2 Standard Primed
A9: SPM294801 | B9: Standard Primed | C9: MDF | D9: 2.9 | E9: 48.5 | F9: 96.5 | G9: 1232 | H9: 2452 | I9: Pcs | J9: CARB P2 | K9: =C9&" "&D9&"mm"&""&"*"&E9&"*"&F9&" "&J9&" "&B9 -> MDF 2.9mm*48.5*96.5 CARB P2 Standard Primed | M9: paint g | N9: g/m2
A10: SPM302701 | B10: Standard Primed | C10: MDF | D10: 3 | E10: 24.5 | F10: 80.5 | G10: 620 | H10: 2045 | I10: Pcs | J10: CARB P2 | K10: =C10&" "&D10&"mm"&""&"*"&E10&"*"&F10&" "&J10&" "&B10 -> MDF 3mm*24.5*80.5 CARB P2 Standard Primed | L10: =H10*G10/1000000 -> 1.2679 | M10: =1.27*2 -> 2.54 | N10: =M10/L10 -> 2.0033126
A11: SPM302702 | B11: Standard Primed | C11: MDF | D11: 3 | E11: 28.5 | F11: 80.5 | G11: 724 | H11: 2045 | I11: Pcs | J11: CARB P2 | K11: =C11&" "&D11&"mm"&""&"*"&E11&"*"&F11&" "&J11&" "&B11 -> MDF 3mm*28.5*80.5 CARB P2 Standard Primed
A12: SPM303701 | B12: Standard Primed | C12: MDF | D12: 3 | E12: 30.5 | F12: 80.5 | G12: 775 | H12: 2045 | I12: Pcs | J12: CARB P2 | K12: =C12&" "&D12&"mm"&""&"*"&E12&"*"&F12&" "&J12&" "&B12 -> MDF 3mm*30.5*80.5 CARB P2 Standard Primed
A13: SPM303702 | B13: Standard Primed | C13: MDF | D13: 3 | E13: 32.5 | F13: 80.5 | G13: 826 | H13: 2045 | I13: Pcs | J13: CARB P2 | K13: =C13&" "&D13&"mm"&""&"*"&E13&"*"&F13&" "&J13&" "&B13 -> MDF 3mm*32.5*80.5 CARB P2 Standard Primed
A14: SPM303705 | B14: Standard Primed | C14: MDF | D14: 3 | E14: 30.5 | F14: 84.5 | G14: 775 | H14: 2145 | I14: Pcs | J14: CARB P2 | K14: =C14&" "&D14&"mm"&""&"*"&E14&"*"&F14&" "&J14&" "&B14 -> MDF 3mm*30.5*84.5 CARB P2 Standard Primed
A15: SPM303703 | B15: Standard Primed | C15: MDF | D15: 3 | E15: 36.5 | F15: 80.5 | G15: 927 | H15: 2045 | I15: Pcs | J15: CARB P2 | K15: =C15&" "&D15&"mm"&""&"*"&E15&"*"&F15&" "&J15&" "&B15 -> MDF 3mm*36.5*80.5 CARB P2 Standard Primed | L15: =H15*G15/1000000 -> 1.895715 | M15: =1.9*2 -> 3.8 | N15: =M15/L15 -> 2.0045207
A16: SPM303704 | B16: Standard Primed | C16: MDF | D16: 3 | E16: 36.5 | F16: 84.5 | G16: 927 | H16: 2145 | I16: Pcs | J16: CARB P2 | K16: =C16&" "&D16&"mm"&""&"*"&E16&"*"&F16&" "&J16&" "&B16 -> MDF 3mm*36.5*84.5 CARB P2 Standard Primed
A17: SPM303801 | B17: Standard Primed | C17: MDF | D17: 3 | E17: 36.5 | F17: 96.5 | G17: 927 | H17: 2452 | I17: Pcs | J17: CARB P2 | K17: =C17&" "&D17&"mm"&""&"*"&E17&"*"&F17&" "&J17&" "&B17 -> MDF 3mm*36.5*96.5 CARB P2 Standard Primed
A18: SPM304801 | B18: Standard Primed | C18: MDF | D18: 3 | E18: 48.5 | F18: 96.5 | G18: 1232 | H18: 2452 | I18: Pcs | J18: CARB P2 | K18: =C18&" "&D18&"mm"&""&"*"&E18&"*"&F18&" "&J18&" "&B18 -> MDF 3mm*48.5*96.5 CARB P2 Standard Primed
A19: UPM302603 | B19: UV prime | C19: MDF | D19: 3 | G19: 730 | H19: 2050 | I19: Pcs | J19: CARB P2 | K19: =C19&" "&D19&"mm"&""&"*"&G19&"*"&H19&" "&J19&" "&B19 -> MDF 3mm*730*2050 CARB P2 UV prime
A20: UPM303604 | B20: UV prime | C20: MDF | D20: 3 | G20: 780 | H20: 2050 | I20: Pcs | J20: CARB P2 | K20: =C20&" "&D20&"mm"&""&"*"&G20&"*"&H20&" "&J20&" "&B20 -> MDF 3mm*780*2050 CARB P2 UV prime
A21: UPM303605 | B21: UV prime | C21: MDF | D21: 3 | G21: 880 | H21: 2050 | I21: Pcs | J21: CARB P2 | K21: =C21&" "&D21&"mm"&""&"*"&G21&"*"&H21&" "&J21&" "&B21 -> MDF 3mm*880*2050 CARB P2 UV prime
A22: UPM303606 | B22: UV prime | C22: MDF | D22: 3 | G22: 930 | H22: 2050 | I22: Pcs | J22: CARB P2 | K22: =C22&" "&D22&"mm"&""&"*"&G22&"*"&H22&" "&J22&" "&B22 -> MDF 3mm*930*2050 CARB P2 UV prime
A23: UPM303607 | B23: UV prime | C23: MDF | D23: 3 | G23: 830 | H23: 2050 | I23: Pcs | J23: CARB P2 | K23: =C23&" "&D23&"mm"&""&"*"&G23&"*"&H23&" "&J23&" "&B23 -> MDF 3mm*830*2050 CARB P2 UV prime
A24: UPM304801 | B24: UV prime | C24: MDF | D24: 3 | E24: 48.5 | F24: 96.5 | G24: 1245 | H24: 2465 | I24: Pcs | J24: CARB P2 | K24: =C24&" "&D24&"mm"&""&"*"&E24&"*"&F24&" "&J24&" "&B24 -> MDF 3mm*48.5*96.5 CARB P2 UV prime
A25: SPFX90001 | B25: UV | C25: FG | D25: 19 | E25: 48.5 | F25: 96.5 | G25: 1232 | H25: 2452 | I25: Pcs | J25: CARB P2 | K25: =C25&" "&D25&"mm"&""&"*"&E25&"*"&F25&" "&J25&" "&B25 -> FG 19mm*48.5*96.5 CARB P2 UV | L25: 油油油
A26: SPM302801 | B26: Standard Primed | C26: MDF | D26: 3 | E26: 24.5 | F26: 96.5 | G26: 620 | H26: 2452 | I26: Pcs | J26: CARB P2 | K26: =C26&" "&D26&"mm"&""&"*"&E26&"*"&F26&" "&J26&" "&B26 -> MDF 3mm*24.5*96.5 CARB P2 Standard Primed
B27: UV prime | C27: Platform MLH | E27: 48.4 | F27: 120.4 | G27: 1230 | H27: 3060 | I27: Pcs | J27: CARB P2 | K27: =C27&" "&D27&"mm"&""&"*"&E27&"*"&F27&" "&J27&" "&B27 -> Platform MLH mm*48.4*120.4 CARB P2 UV prime
B28: UV prime | C28: MDF | D28: 3 | G28: 927 | H28: 2050 | I28: Pcs | J28: CARB P2 | K28: =C28&" "&D28&"mm"&""&"*"&E28&"*"&F28&" "&J28&" "&B28 -> MDF 3mm** CARB P2 UV prime
A29: 4WBXX9CU1 | B29: W.BIRCH C UV/UV PRIMED | C29: VCMX | D29: 19 | E29: 48.5 | F29: 96.5 | G29: 1232 | H29: 2452 | I29: Pcs | J29: CARB P2 | K29: =C29&" "&D29&"mm"&""&"*"&E29&"*"&F29&" "&J29&" "&B29 -> VCMX 19mm*48.5*96.5 CARB P2 W.BIRCH C UV/UV PRIMED | L29: 4x8
A30: 4NOXX9UU1 | B30: UV PRIMED/UV PRIMED | C30: VCMX | D30: 19 | E30: 48.5 | F30: 96.5 | G30: 1232 | H30: 2452 | I30: Pcs | J30: CARB P2 | K30: =C30&" "&D30&"mm"&""&"*"&E30&"*"&F30&" "&J30&" "&B30 -> VCMX 19mm*48.5*96.5 CARB P2 UV PRIMED/UV PRIMED | L30: 4x8
A31: 4WMPX9B29 | B31: W.MAPLE B UV / #2 UV | C31: Platform JS | D31: 19 | E31: 48.5 | F31: 96.5 | G31: 1232 | H31: 2452 | I31: Pcs | J31: CARB P2 | K31: =C31&" "&D31&"mm"&""&"*"&E31&"*"&F31&" "&J31&" "&B31 -> Platform JS 19mm*48.5*96.5 CARB P2 W.MAPLE B UV / #2 UV | L31: 4x8
A32: 4WMPX9B2A | B32: W.MAPLE B UV / #2 | C32: PlatformJS | D32: 19 | E32: 48.5 | F32: 96.5 | G32: 1232 | H32: 2452 | I32: Pcs | J32: CARB P2 | K32: =C32&" "&D32&"mm"&""&"*"&E32&"*"&F32&" "&J32&" "&B32 -> PlatformJS 19mm*48.5*96.5 CARB P2 W.MAPLE B UV / #2 | L32: 4x8
A33: 4WBPX9CD2 | B33: W.BIRCH C UV / D UV | C33: PlatformJS | D33: 19 | E33: 48.5 | F33: 96.5 | G33: 1232 | H33: 2452 | I33: Pcs | J33: CARB P2 | K33: =C33&" "&D33&"mm"&""&"*"&E33&"*"&F33&" "&J33&" "&B33 -> PlatformJS 19mm*48.5*96.5 CARB P2 W.BIRCH C UV / D UV | L33: 4x8
A34: 4WBPX9DD5 | B34: W.BIRCH D+ UV / D UV | C34: PlatformJS | D34: 19 | E34: 48.5 | F34: 96.5 | G34: 1232 | H34: 2452 | I34: Pcs | J34: CARB P2 | K34: =C34&" "&D34&"mm"&""&"*"&E34&"*"&F34&" "&J34&" "&B34 -> PlatformJS 19mm*48.5*96.5 CARB P2 W.BIRCH D+ UV / D UV | L34: 4x8
A35: 4NOXX2UU2 | B35: UV PRIMED/UV PRIMED | C35: VCMX | D35: 12.5 | E35: 48.5 | F35: 96.5 | G35: 1232 | H35: 2452 | I35: Pcs | J35: CARB P2 | K35: =C35&" "&D35&"mm"&""&"*"&E35&"*"&F35&" "&J35&" "&B35 -> VCMX 12.5mm*48.5*96.5 CARB P2 UV PRIMED/UV PRIMED | L35: 4x8
A36: 4NOXX9UU2 | B36: UV PRIMED/UV PRIMED | C36: VCMX | D36: 12.5 | E36: 48.5 | F36: 120.5 | G36: 1232 | H36: 3060 | I36: Pcs | J36: CARB P2 | K36: =C36&" "&D36&"mm"&""&"*"&E36&"*"&F36&" "&J36&" "&B36 -> VCMX 12.5mm*48.5*120.5 CARB P2 UV PRIMED/UV PRIMED | L36: 4x8
A37: SPM302703 | B37: Standard Primed | C37: MDF | D37: 3 | E37: 24.5 | F37: 84.5 | G37: 620 | H37: 2145 | I37: Pcs | J37: CARB P2 | K37: =C37&" "&D37&"mm"&""&"*"&E37&"*"&F37&" "&J37&" "&B37 -> MDF 3mm*24.5*84.5 CARB P2 Standard Primed
A38: 4WMPX9C25 | B38: W.MAPLE C UV / #2 UV | C38: PlatformJS | D38: 19 | E38: 48.5 | F38: 96.5 | G38: 1232 | H38: 2452 | I38: Pcs | J38: CARB P2 | K38: =C38&" "&D38&"mm"&""&"*"&E38&"*"&F38&" "&J38&" "&B38 -> PlatformJS 19mm*48.5*96.5 CARB P2 W.MAPLE C UV / #2 UV | L38: 4x8
A39: 470 | B39: Standard Primed | C39: MDF | D39: 3 | E39: 18.5 | F39: 80.5 | G39: 470 | H39: 2045 | I39: Pcs | J39: CARB P2 | K39: =C39&" "&D39&"mm"&""&"*"&E39&"*"&F39&" "&J39&" "&B39 -> MDF 3mm*18.5*80.5 CARB P2 Standard Primed
A40: 2.3*620 | B40: Standard Primed | C40: MDF | D40: 2.3 | E40: 24.5 | F40: 80.5 | G40: 620 | H40: 2045 | I40: Pcs | J40: CARB P2 | K40: =C40&" "&D40&"mm"&""&"*"&E40&"*"&F40&" "&J40&" "&B40 -> MDF 2.3mm*24.5*80.5 CARB P2 Standard Primed
...

Sheet V
A1: Code 编码 | B1: Species 树种 | C1: V-THI 厚度 | D1: Width 宽(mm) | E1: Length长(mm) | F1: F/B 面底 | G1: Cut 纹理 | H1: Grade 等级 | I1: Mat. 拼接 | J1: FSC | K1: Unit 单位 | L1: 类别 | M1: Code 编码
A2: RG-XALPB102 | B2: ALDER | C2: 0.25 | D2: 1265 | E2: 2520 | F2: BACK | G2: PC | H2: #1 | I2: BM | K2: Pcs | L2: 48-自贴 | M2: =RIGHT(A2,8) -> XALPB102
A3: XALPB102 | B3: ALDER | C3: 0.25 | D3: 1265 | E3: 2520 | F3: BACK | G3: PC | H3: #1 | I3: BM | K3: Pcs | L3: 48-自贴 | M3: =RIGHT(A3,8) -> XALPB102
A4: RG-XALPB101 | B4: ALDER | C4: 0.5 | D4: 1265 | E4: 1900 | F4: BACK | G4: PC | H4: #1 | I4: BM | K4: Pcs | L4: 48-自贴 | M4: =RIGHT(A4,8) -> XALPB101
A5: XALPB101 | B5: ALDER | C5: 0.5 | D5: 1265 | E5: 1900 | F5: BACK | G5: PC | H5: #1 | I5: BM | K5: Pcs | L5: 48-自贴 | M5: =RIGHT(A5,8) -> XALPB101
A6: RG-XALPM101 | B6: ALDER | C6: 0.5 | D6: 1265 | E6: 2520 | F6: BACK | G6: PC | H6: #1 | I6: MPF | K6: Pcs | L6: 48-自贴 | M6: =RIGHT(A6,8) -> XALPM101
A7: XALPM101 | B7: ALDER | C7: 0.5 | D7: 1265 | E7: 2520 | F7: BACK | G7: PC | H7: #1 | I7: MPF | K7: Pcs | L7: 48-自贴 | M7: =RIGHT(A7,8) -> XALPM101
A8: RG-XALPS101 | B8: ALDER | C8: 0.5 | D8: 1265 | E8: 1900 | F8: BACK | G8: PC | H8: #1 | I8: SM | K8: Pcs | L8: 48-自贴 | M8: =RIGHT(A8,8) -> XALPS101
A9: XALPS101 | B9: ALDER | C9: 0.5 | D9: 1265 | E9: 1900 | F9: BACK | G9: PC | H9: #1 | I9: SM | K9: Pcs | L9: 48-自贴 | M9: =RIGHT(A9,8) -> XALPS101
A10: RG-XALPM102 | B10: ALDER | C10: 0.5 | D10: 1265 | E10: 2520 | F10: BACK | G10: PC | H10: #1 IKE | I10: MPF | K10: Pcs | L10: 48-自贴 | M10: =RIGHT(A10,8) -> XALPM102
A11: XALPM102 | B11: ALDER | C11: 0.5 | D11: 1265 | E11: 2520 | F11: BACK | G11: PC | H11: #1 IKE | I11: MPF | K11: Pcs | L11: 48-自贴 | M11: =RIGHT(A11,8) -> XALPM102
A12: RG-XALPP102 | B12: ALDER | C12: 0.5 | D12: 1265 | E12: 2520 | F12: BACK | G12: PC | H12: #1 IKE | I12: PM | K12: Pcs | L12: 48-自贴 | M12: =RIGHT(A12,8) -> XALPP102
A13: XALPP102 | B13: ALDER | C13: 0.5 | D13: 1265 | E13: 2520 | F13: BACK | G13: PC | H13: #1 IKE | I13: PM | K13: Pcs | L13: 48-自贴 | M13: =RIGHT(A13,8) -> XALPP102
... A123: XBERSB02 | B123: BEECH | C123: 0.5 | D123: 1265 | E123: 2520 | F123: FACE | G123: RC | H123: B NO FIG | I123: SM | K123: Pcs | L123: 48-自贴 | M123: =RIGHT(A123,8) -> XBERSB02
A124: RG-XCEPZA01 | B124: CEDAR | C124: 0.5 | D124: NON | E124: 2500 | F124: Z | G124: PC | H124: A | I124: Z | K124: M2 | L124: m2 | M124: =RIGHT(A124,8) -> XCEPZA01
A125: XCEPZA01 | B125: CEDAR | C125: 0.5 | D125: NON | E125: 2500 | F125: Z | G125: PC | H125: A | I125: Z | K125: M2 | L125: m2 | M125: =RIGHT(A125,8) -> XCEPZA01
A126: RG-XCEPPA01 | B126: CEDAR | C126: 0.5 | D126: 1265 | E126: 2520 | F126: FACE | G126: PC | H126: A | I126: PM | K126: Pcs | L126: 48-自贴 | M126: =RIGHT(A126,8) -> XCEPPA01
A127: XCEPPA01 | B127: CEDAR | C127: 0.5 | D127: 1265 | E127: 2520 | F127: FACE | G127: PC | H127: A | I127: PM | K127: Pcs | L127: 48-自贴 | M127: =RIGHT(A127,8) -> XCEPPA01
A128: RG-XCHPB101 | B128: CHERRY | C128: 0.5 | D128: 1265 | E128: 2520 | F128: BACK | G128: PC | H128: #1 | I128: BM | K128: Pcs | L128: 48-自贴 | M128: =RIGHT(A128,8) -> XCHPB101
A129: XCHPB101 | B129: CHERRY | C129: 0.5 | D129: 1265 | E129: 2520 | F129: BACK | G129: PC | H129: #1 | I129: BM | K129: Pcs | L129: 48-自贴 | M129: =RIGHT(A129,8) -> XCHPB101
A130: RG-XCHPM101 | B130: CHERRY | C130: 0.5 | D130: 1265 | E130: 2520 | F130: BACK | G130: PC | H130: #1 | I130: MPF | K130: Pcs | L130: 48-自贴 | M130: =RIGHT(A130,8) -> XCHPM101
A131: XCHPM101 | B131: CHERRY | C131: 0.5 | D131: 1265 | E131: 2520 | F131: BACK | G131: PC | H131: #1 | I131: MPF | K131: Pcs | L131: 48-自贴 | M131: =RIGHT(A131,8) -> XCHPM101
A132: RG-XCHPM201 | B132: CHERRY | C132: 0.5 | D132: 1265 | E132: 2520 | F132: BACK | G132: PC | H132: #2 | I132: MPF | K132: Pcs | L132: 48-自贴 | M132: =RIGHT(A132,8) -> XCHPM201
A133: XCHPM201 | B133: CHERRY | C133: 0.5 | D133: 1265 | E133: 2520 | F133: BACK | G133: PC | H133: #2 | I133: MPF | K133: Pcs | L133: 48-自贴 | M133: =RIGHT(A133,8) -> XCHPM201
A134: RG-XCHPBA01 | B134: CHERRY | C134: 0.5 | D134: 1265 | E134: 2520 | F134: FACE | G134: PC | H134: A | I134: BM | K134: Pcs | L134: 48-自贴 | M134: =RIGHT(A134,8) -> XCHPBA01
A135: XCHPBA01 | B135: CHERRY | C135: 0.5 | D135: 1265 | E135: 2520 | F135: FACE | G135: PC | H135: A | I135: BM | K135: Pcs | L135: 48-自贴 | M135: =RIGHT(A135,8) -> XCHPBA01
A136: RG-XCHPBA02 | B136: CHERRY | C136: 0.5 | D136: 1265 | E136: 2520 | F136: FACE | G136: PC | H136: A SQ&N | I136: BM | K136: Pcs | L136: 48-自贴 | M136: =RIGHT(A136,8) -> XCHPBA02
A137: XCHPBA02 | B137: CHERRY | C137: 0.5 | D137: 1265 | E137: 2520 | F137: FACE | G137: PC | H137: A SQ&N | I137: BM | K137: Pcs | L137: 48-自贴 | M137: =RIGHT(A137,8) -> XCHPBA02
... A177: XCYPPR01 | B177: CYPRESS | C177: 0.5 | D177: 1265 | E177: 2520 | F177: FACE | G177: PC | H177: Rustic | I177: PM | K177: Pcs | L177: 48-自贴 | M177: =RIGHT(A177,8) -> XCYPPR01
A178: RG-XENRWF11 | B178: Engineered Hardwood | C178: 0.15 | D178: 630 | E178: 2200 | F178: FACE | G178: RC | H178: FD | I178: WPF | J178: FSC 100% | K178: Pcs | L178: RES-door | M178: =RIGHT(A178,8) -> XENRWF11
A179: RG-XENRWF12 | B179: Engineered Hardwood | C179: 0.15 | D179: 730 | E179: 2200 | F179: FACE | G179: RC | H179: FD | I179: WPF | J179: FSC 100% | K179: Pcs | L179: RES-door | M179: =RIGHT(A179,8) -> XENRWF12
A180: RG-XENRWF13 | B180: Engineered Hardwood | C180: 0.15 | D180: 780 | E180: 2200 | F180: FACE | G180: RC | H180: FD | I180: WPF | J180: FSC 100% | K180: Pcs | L180: RES-door | M180: =RIGHT(A180,8) -> XENRWF13
A181: RG-XENRWF14 | B181: Engineered Hardwood | C181: 0.15 | D181: 930 | E181: 2200 | F181: FACE | G181: RC | H181: FD | I181: WPF | J181: FSC 100% | K181: Pcs | L181: RES-door | M181: =RIGHT(A181,8) -> XENRWF14
A182: RG-XENRWF17 | B182: Engineered Hardwood | C182: 0.15 | D182: 830 | E182: 2200 | F182: FACE | G182: RC | H182: FD | I182: WPF | J182: FSC 100% | K182: Pcs | L182: RES-door | M182: =RIGHT(A182,8) -> XENRWF17
A183: XENRWF11 | B183: Engineered Hardwood | C183: 0.15 | D183: 630 | E183: 2200 | F183: FACE | G183: RC | H183: FD | I183: WPF | J183: FSC 100% | K183: Pcs | L183: RES-door | M183: =RIGHT(A183,8) -> XENRWF11
A184: XENRWF12 | B184: Engineered Hardwood | C184: 0.15 | D184: 730 | E184: 2200 | F184: FACE | G184: RC | H184: FD | I184: WPF | J184: FSC 100% | K184: Pcs | L184: RES-door | M184: =RIGHT(A184,8) -> XENRWF12
A185: XENRWF13 | B185: Engineered Hardwood | C185: 0.15 | D185: 780 | E185: 2200 | F185: FACE | G185: RC | H185: FD | I185: WPF | J185: FSC 100% | K185: Pcs | L185: RES-door | M185: =RIGHT(A185,8) -> XENRWF13
A186: XENRWF14 | B186: Engineered Hardwood | C186: 0.15 | D186: 930 | E186: 2200 | F186: FACE | G186: RC | H186: FD | I186: WPF | J186: FSC 100% | K186: Pcs | L186: RES-door | M186: =RIGHT(A186,8) -> XENRWF14
A187: XENRWF17 | B187: Engineered Hardwood | C187: 0.15 | D187: 830 | E187: 2200 | F187: FACE | G187: RC | H187: FD | I187: WPF | J187: FSC 100% | K187: Pcs | L187: RES-door | M187: =RIGHT(A187,8) -> XENRWF17
A188: RG-XENRWF15 | B188: Engineered Hardwood | C188: 0.15 | D188: 930 | E188: 2460 | F188: FACE | G188: RC | H188: FD | I188: WPF | J188: FSC 100% | K188: Pcs | L188: RES-door | M188: =RIGHT(A188,8) -> XENRWF15
...

Sheet M2
A1: Code 编码 | B1: Species 树种 | C1: V-THI 厚度 | D1: Width 宽(mm) | E1: Length长(mm) | F1: F/B 面底 | G1: Cut 纹理 | H1: Grade 等级 | I1: Mat. 拼接 | J1: FSC | K1: Unit 单位 | L1: Name
A2: XWAPZA09 | B2: Walnut | C2: 0.42 | D2: NON | E2: 2500 | F2: Z | G2: PC | H2: P AA | I2: Z | K2: M2 | L2: =B2&" "&C2&"x"&D2&"x"&E2&"mm "&H2&" "&G2&" "&I2 -> Walnut 0.42xNONx2500mm P AA PC Z | M2: ALDER 0.5mm 1265x2520 Grade#1 Rustic PC PM
A3: XWAPZA10 | B3: Walnut | C3: 0.42 | D3: NON | E3: 2500 | F3: Z | G3: PC | H3: PA | I3: Z | K3: M2 | L3: =B3&" "&C3&"x"&D3&"x"&E3&"mm "&H3&" "&G3&" "&I3 -> Walnut 0.42xNONx2500mm PA PC Z
A4: XWAPZJ02 | B4: Walnut | C4: 0.42 | D4: NON | E4: 2500 | F4: Z | G4: PC | H4: PT J8 | I4: Z | K4: M2 | L4: =B4&" "&C4&"x"&D4&"x"&E4&"mm "&H4&" "&G4&" "&I4 -> Walnut 0.42xNONx2500mm PT J8 PC Z
A5: XWAPZJ01 | B5: Walnut | C5: 0.5 | D5: NON | E5: 2500 | F5: Z | G5: PC | H5: PT J8 | I5: Z | K5: M2 | L5: =B5&" "&C5&"x"&D5&"x"&E5&"mm "&H5&" "&G5&" "&I5 -> Walnut 0.5xNONx2500mm PT J8 PC Z
A6: XBEPZB02 | B6: BEECH | C6: 0.5 | D6: NON | E6: Natural | F6: Z | G6: Z | H6: Z | I6: Z | K6: m2 | L6: =B6&" "&C6&"x"&D6&"x"&E6&"mm "&H6&" "&G6&" "&I6 -> BEECH 0.5xNONxNaturalmm Z Z Z
A7: XCEPZA01 | B7: CEDAR | C7: 0.5 | D7: NON | E7: 2500 | F7: Z | G7: PC | H7: A | I7: Z | K7: m2 | L7: =B7&" "&C7&"x"&D7&"x"&E7&"mm "&H7&" "&G7&" "&I7 -> CEDAR 0.5xNONx2500mm A PC Z
A8: YCHPA801 | B8: CHERRY | C8: 0.4 | D8: NON | E8: 2500 | F8: Z | G8: PC | H8: PA | K8: M2 | L8: =B8&" "&C8&"x"&D8&"x"&E8&"mm "&H8&" "&G8&" "&I8 -> CHERRY 0.4xNONx2500mm PA PC
A9: XCHPZA02 | B9: CHERRY | C9: 0.42 | D9: NON | E9: 2500+ | F9: Z | G9: PC | H9: A | K9: m2 | L9: =B9&" "&C9&"x"&D9&"x"&E9&"mm "&H9&" "&G9&" "&I9 -> CHERRY 0.42xNONx2500+mm A PC
A10: XCHPZC01 | B10: CHERRY | C10: 0.45 | D10: NON | E10: 2550+ | F10: FACE | G10: PC | H10: C | K10: m2 | L10: =B10&" "&C10&"x"&D10&"x"&E10&"mm "&H10&" "&G10&" "&I10 -> CHERRY 0.45xNONx2550+mm C PC
A11: XCHPZC02 | B11: CHERRY | C11: 0.45 | D11: NON | E11: 2500+ | F11: Z | G11: PC | H11: C | K11: m2 | L11: =B11&" "&C11&"x"&D11&"x"&E11&"mm "&H11&" "&G11&" "&I11 -> CHERRY 0.45xNONx2500+mm C PC
A12: XCHPZB02 | B12: CHERRY | C12: 0.5 | D12: NON | E12: 2500+ | F12: Z | G12: PC | H12: B | K12: m2 | L12: =B12&" "&C12&"x"&D12&"x"&E12&"mm "&H12&" "&G12&" "&I12 -> CHERRY 0.5xNONx2500+mm B PC
A13: XCHPZC03 | B13: CHERRY | C13: 0.5 | D13: NON | E13: 2500+ | F13: Z | G13: PC | H13: C | K13: m2 | L13: =B13&" "&C13&"x"&D13&"x"&E13&"mm "&H13&" "&G13&" "&I13 -> CHERRY 0.5xNONx2500+mm C PC
A14: XROPZA02 | B14: R.OAK | C14: 0.4 | D14: NON | E14: 2500+ | F14: Z | G14: PC | H14: 1A | I14: Z | J14: FSC CW | K14: m2 | L14: =B14&" "&C14&"x"&D14&"x"&E14&"mm "&H14&" "&G14&" "&I14 -> R.OAK 0.4xNONx2500+mm 1A PC Z
A15: XROPZA03 | B15: R.OAK | C15: 0.4 | D15: NON | E15: 2500+ | F15: Z | G15: PC | H15: 2A | I15: Z | J15: FSC CW | K15: m2 | L15: =B15&" "&C15&"x"&D15&"x"&E15&"mm "&H15&" "&G15&" "&I15 -> R.OAK 0.4xNONx2500+mm 2A PC Z
A16: YROPA802 | B16: R.OAK | C16: 0.4 | D16: NON | E16: 2500 | F16: Z | G16: PC | H16: PAA | I16: Z | J16: FSC CW | K16: M2 | L16: =B16&" "&C16&"x"&D16&"x"&E16&"mm "&H16&" "&G16&" "&I16 -> R.OAK 0.4xNONx2500mm PAA PC Z
A17: XROPZA04 | B17: R.OAK | C17: 0.4 | D17: NON | E17: 2500+ | F17: Z | G17: PC | H17: Panel A | I17: Z | K17: m2 | L17: =B17&" "&C17&"x"&D17&"x"&E17&"mm "&H17&" "&G17&" "&I17 -> R.OAK 0.4xNONx2500+mm Panel A PC Z
A18: XRORZA01 | B18: R.OAK | C18: 0.4 | D18: NON | E18: 2500+ | F18: Z | G18: RC | H18: Panel A | I18: Z | K18: m2 | L18: =B18&" "&C18&"x"&D18&"x"&E18&"mm "&H18&" "&G18&" "&I18 -> R.OAK 0.4xNONx2500+mm Panel A RC Z
A19: XROPZ201 | B19: R.OAK | C19: 0.45 | D19: NON | E19: 2500+ | F19: Z | G19: PC | H19: #2 | I19: Z | K19: m2 | L19: =B19&" "&C19&"x"&D19&"x"&E19&"mm "&H19&" "&G19&" "&I19 -> R.OAK 0.45xNONx2500+mm #2 PC Z
A20: XROPZB01 | B20: R.OAK | C20: 0.45 | D20: NON | E20: 2500+ | F20: Z | G20: PC | H20: B | I20: Z | K20: m2 | L20: =B20&" "&C20&"x"&D20&"x"&E20&"mm "&H20&" "&G20&" "&I20 -> R.OAK 0.45xNONx2500+mm B PC Z
A21: XROPZZ01 | B21: R.OAK | C21: 0.45 | D21: NON | E21: 2550+ | F21: Face | G21: PC | H21: Z | I21: Z | K21: m2 | L21: =B21&" "&C21&"x"&D21&"x"&E21&"mm "&H21&" "&G21&" "&I21 -> R.OAK 0.45xNONx2550+mm Z PC Z
A22: XROPZ202 | B22: R.OAK | C22: 0.5 | D22: NON | E22: 2500+ | F22: Z | G22: PC | H22: #2 | I22: Z | K22: m2 | L22: =B22&" "&C22&"x"&D22&"x"&E22&"mm "&H22&" "&G22&" "&I22 -> R.OAK 0.5xNONx2500+mm #2 PC Z
A23: XROPZA01 | B23: R.OAK | C23: 0.5 | D23: NON | E23: 2500+ | F23: Z | G23: PC | H23: A | I23: Z | K23: m2 | L23: =B23&" "&C23&"x"&D23&"x"&E23&"mm "&H23&" "&G23&" "&I23 -> R.OAK 0.5xNONx2500+mm A PC Z
A24: XROPZB02 | B24: R.OAK | C24: 0.5 | D24: NON | E24: 2500+ | F24: Z | G24: PC | H24: B | I24: Z | K24: m2 | L24: =B24&" "&C24&"x"&D24&"x"&E24&"mm "&H24&" "&G24&" "&I24 -> R.OAK 0.5xNONx2500+mm B PC Z
A25: YROPA801 | B25: R.OAK | C25: 0.5 | D25: NON | E25: 2500 | F25: Z | G25: PC | H25: PAA | I25: Z | J25: FSC CW | K25: M2 | L25: =B25&" "&C25&"x"&D25&"x"&E25&"mm "&H25&" "&G25&" "&I25 -> R.OAK 0.5xNONx2500mm PAA PC Z
A26: XROFZZ01 | B26: R.OAK | C26: 0.5 | D26: NON | E26: 2500/3500 | F26: Z | G26: Rift | H26: Z | I26: Z | K26: m2 | L26: =B26&" "&C26&"x"&D26&"x"&E26&"mm "&H26&" "&G26&" "&I26 -> R.OAK 0.5xNONx2500/3500mm Z Rift Z
A27: XASPZB02 | B27: W.ASH | C27: 0.5 | D27: NON | E27: Natural | F27: Z | G27: Z | H27: Z | I27: Z | K27: m2 | L27: =B27&" "&C27&"x"&D27&"x"&E27&"mm "&H27&" "&G27&" "&I27 -> W.ASH 0.5xNONxNaturalmm Z Z Z
A28: XWBRZZ01 | B28: W.BIRCH | C28: 0.5 | D28: NON | E28: 2200/2500 | F28: Z | G28: RC | H28: Z | I28: Z | K28: m2 | L28: =B28&" "&C28&"x"&D28&"x"&E28&"mm "&H28&" "&G28&" "&I28 -> W.BIRCH 0.5xNONx2200/2500mm Z RC Z
A29: XWMRZ301 | B29: W.MAPLE | C29: 0.4 | D29: NON | E29: 2500 | F29: Z | G29: RC | H29: #3 SPL | I29: Z | J29: FSC CW | K29: m2 | L29: =B29&" "&C29&"x"&D29&"x"&E29&"mm "&H29&" "&G29&" "&I29 -> W.MAPLE 0.4xNONx2500mm #3 SPL RC Z
A30: XWMPZA31 | B30: W.MAPLE | C30: 0.5 | D30: NON | E30: 2250/2500 | F30: Z | G30: PC | H30: Door A | I30: Z | J30: FSC CW | K30: m2 | L30: =B30&" "&C30&"x"&D30&"x"&E30&"mm "&H30&" "&G30&" "&I30 -> W.MAPLE 0.5xNONx2250/2500mm Door A PC Z
A31: XWMPZA32 | B31: W.MAPLE | C31: 0.5 | D31: NON | E31: 2250/2500 | F31: Z | G31: PC | H31: Door AB | I31: Z | J31: FSC CW | K31: m2 | L31: =B31&" "&C31&"x"&D31&"x"&E31&"mm "&H31&" "&G31&" "&I31 -> W.MAPLE 0.5xNONx2250/2500mm Door AB PC Z
A32: XWMPZB31 | B32: W.MAPLE | C32: 0.5 | D32: NON | E32: 2250/2500 | F32: Z | G32: PC | H32: Door B | I32: Z | J32: FSC CW | K32: m2 | L32: =B32&" "&C32&"x"&D32&"x"&E32&"mm "&H32&" "&G32&" "&I32 -> W.MAPLE 0.5xNONx2250/2500mm Door B PC Z
A33: XWMPZA33 | B33: W.MAPLE | C33: 0.5 | D33: NON | E33: 2250/3050 | F33: Z | G33: PC | H33: Panel A | I33: Z | J33: FSC CW | K33: m2 | L33: =B33&" "&C33&"x"&D33&"x"&E33&"mm "&H33&" "&G33&" "&I33 -> W.MAPLE 0.5xNONx2250/3050mm Panel A PC Z
A34: XWMPZA36 | B34: W.MAPLE | C34: 0.5 | D34: NON | E34: 2250/3050 | F34: Z | G34: PC | H34: Panel AA | I34: Z | J34: FSC CW | K34: m2 | L34: =B34&" "&C34&"x"&D34&"x"&E34&"mm "&H34&" "&G34&" "&I34 -> W.MAPLE 0.5xNONx2250/3050mm Panel AA PC Z
A35: XWMPZA35 | B35: W.MAPLE | C35: 0.5 | D35: NON | E35: 2250/3050 | F35: Z | G35: PC | H35: Panel AB | I35: Z | J35: FSC CW | K35: m2 | L35: =B35&" "&C35&"x"&D35&"x"&E35&"mm "&H35&" "&G35&" "&I35 -> W.MAPLE 0.5xNONx2250/3050mm Panel AB PC Z
A36: XWMPZB32 | B36: W.MAPLE | C36: 0.5 | D36: NON | E36: 2250/3050 | F36: Z | G36: PC | H36: Panel B | I36: Z | J36: FSC CW | K36: m2 | L36: =B36&" "&C36&"x"&D36&"x"&E36&"mm "&H36&" "&G36&" "&I36 -> W.MAPLE 0.5xNONx2250/3050mm Panel B PC Z
A37: XWOQZA02 | B37: W.OAK | C37: 0.4 | D37: NON | E37: 2550+ | F37: Face | G37: QC | H37: Panel A | I37: Z | J37: FSC CW | K37: m2 | L37: =B37&" "&C37&"x"&D37&"x"&E37&"mm "&H37&" "&G37&" "&I37 -> W.OAK 0.4xNONx2550+mm Panel A QC Z
A38: YWOFA802 | B38: W.OAK | C38: 0.4 | D38: NON | E38: 2500 | F38: Z | G38: RIFT | H38: PAA | I38: Z | K38: m2 | L38: =B38&" "&C38&"x"&D38&"x"&E38&"mm "&H38&" "&G38&" "&I38 -> W.OAK 0.4xNONx2500mm PAA RIFT Z
A39: YWOFA803 | B39: W.OAK | C39: 0.4 | D39: NON | E39: 2500 | F39: Z | G39: RIFT | H39: PA | I39: Z | K39: m2 | L39: =B39&" "&C39&"x"&D39&"x"&E39&"mm "&H39&" "&G39&" "&I39 -> W.OAK 0.4xNONx2500mm PA RIFT Z
A40: YWOFA804 | B40: W.OAK | C40: 0.4 | D40: NON | E40: 2500 | F40: Z | G40: RIFT | H40: PAB | I40: Z | K40: m2 | L40: =B40&" "&C40&"x"&D40&"x"&E40&"mm "&H40&" "&G40&" "&I40 -> W.OAK 0.4xNONx2500mm PAB RIFT Z
...
